2024-05-28 11:54:06,262 INFO    MainThread:47574 [wandb_setup.py:_flush():76] Current SDK version is 0.17.0
2024-05-28 11:54:06,262 INFO    MainThread:47574 [wandb_setup.py:_flush():76] Configure stats pid to 47574
2024-05-28 11:54:06,263 INFO    MainThread:47574 [wandb_setup.py:_flush():76] Loading settings from /home/alessiatortone/.config/wandb/settings
2024-05-28 11:54:06,263 INFO    MainThread:47574 [wandb_setup.py:_flush():76] Loading settings from /home/alessiatortone/ProjectMLDL/wandb/settings
2024-05-28 11:54:06,263 INFO    MainThread:47574 [wandb_setup.py:_flush():76] Loading settings from environment variables: {}
2024-05-28 11:54:06,263 INFO    MainThread:47574 [wandb_setup.py:_flush():76] Applying setup settings: {'_disable_service': False}
2024-05-28 11:54:06,263 INFO    MainThread:47574 [wandb_setup.py:_flush():76] Inferring run settings from compute environment: {'program_relpath': 'test_sb3.py', 'program_abspath': '/home/alessiatortone/ProjectMLDL/test_sb3.py', 'program': 'test_sb3.py'}
2024-05-28 11:54:06,263 INFO    MainThread:47574 [wandb_setup.py:_flush():76] Applying login settings: {}
2024-05-28 11:54:06,263 INFO    MainThread:47574 [wandb_init.py:_log_setup():520] Logging user logs to /home/alessiatortone/ProjectMLDL/wandb/run-20240528_115406-5lpsqv81/logs/debug.log
2024-05-28 11:54:06,264 INFO    MainThread:47574 [wandb_init.py:_log_setup():521] Logging internal logs to /home/alessiatortone/ProjectMLDL/wandb/run-20240528_115406-5lpsqv81/logs/debug-internal.log
2024-05-28 11:54:06,264 INFO    MainThread:47574 [wandb_init.py:init():560] calling init triggers
2024-05-28 11:54:06,264 INFO    MainThread:47574 [wandb_init.py:init():568] wandb.init called with sweep_config: {}
config: {}
2024-05-28 11:54:06,264 INFO    MainThread:47574 [wandb_init.py:init():610] starting backend
2024-05-28 11:54:06,264 INFO    MainThread:47574 [wandb_init.py:init():614] setting up manager
2024-05-28 11:54:06,268 INFO    MainThread:47574 [backend.py:_multiprocessing_setup():107] multiprocessing start_methods=fork,spawn,forkserver, using: spawn
2024-05-28 11:54:06,269 INFO    MainThread:47574 [wandb_init.py:init():622] backend started and connected
2024-05-28 11:54:06,272 INFO    MainThread:47574 [wandb_init.py:init():711] updated telemetry
2024-05-28 11:54:06,286 INFO    MainThread:47574 [wandb_init.py:init():744] communicating run to backend with 90.0 second timeout
2024-05-28 11:54:34,896 INFO    Thread-1  :47574 [retry.py:__call__():172] Retry attempt failed:
Traceback (most recent call last):
  File "/home/alessiatortone/miniconda3/envs/mldl/lib/python3.7/site-packages/urllib3/connection.py", line 207, in _new_conn
    socket_options=self.socket_options,
  File "/home/alessiatortone/miniconda3/envs/mldl/lib/python3.7/site-packages/urllib3/util/connection.py", line 60, in create_connection
    for res in socket.getaddrinfo(host, port, family, socket.SOCK_STREAM):
  File "/home/alessiatortone/miniconda3/envs/mldl/lib/python3.7/socket.py", line 752, in getaddrinfo
    for res in _socket.getaddrinfo(host, port, family, type, proto, flags):
socket.gaierror: [Errno -3] Temporary failure in name resolution

The above exception was the direct cause of the following exception:

Traceback (most recent call last):
  File "/home/alessiatortone/miniconda3/envs/mldl/lib/python3.7/site-packages/urllib3/connectionpool.py", line 803, in urlopen
    **response_kw,
  File "/home/alessiatortone/miniconda3/envs/mldl/lib/python3.7/site-packages/urllib3/connectionpool.py", line 492, in _make_request
    raise new_e
  File "/home/alessiatortone/miniconda3/envs/mldl/lib/python3.7/site-packages/urllib3/connectionpool.py", line 468, in _make_request
    self._validate_conn(conn)
  File "/home/alessiatortone/miniconda3/envs/mldl/lib/python3.7/site-packages/urllib3/connectionpool.py", line 1097, in _validate_conn
    conn.connect()
  File "/home/alessiatortone/miniconda3/envs/mldl/lib/python3.7/site-packages/urllib3/connection.py", line 611, in connect
    self.sock = sock = self._new_conn()
  File "/home/alessiatortone/miniconda3/envs/mldl/lib/python3.7/site-packages/urllib3/connection.py", line 210, in _new_conn
    raise NameResolutionError(self.host, self, e) from e
urllib3.exceptions.NameResolutionError: <urllib3.connection.HTTPSConnection object at 0x7efd28452610>: Failed to resolve 'api.wandb.ai' ([Errno -3] Temporary failure in name resolution)

The above exception was the direct cause of the following exception:

Traceback (most recent call last):
  File "/home/alessiatortone/miniconda3/envs/mldl/lib/python3.7/site-packages/requests/adapters.py", line 497, in send
    chunked=chunked,
  File "/home/alessiatortone/miniconda3/envs/mldl/lib/python3.7/site-packages/urllib3/connectionpool.py", line 846, in urlopen
    method, url, error=new_e, _pool=self, _stacktrace=sys.exc_info()[2]
  File "/home/alessiatortone/miniconda3/envs/mldl/lib/python3.7/site-packages/urllib3/util/retry.py", line 515, in increment
    raise MaxRetryError(_pool, url, reason) from reason  # type: ignore[arg-type]
urllib3.exceptions.MaxRetryError: HTTPSConnectionPool(host='api.wandb.ai', port=443): Max retries exceeded with url: /graphql (Caused by NameResolutionError("<urllib3.connection.HTTPSConnection object at 0x7efd28452610>: Failed to resolve 'api.wandb.ai' ([Errno -3] Temporary failure in name resolution)"))

During handling of the above exception, another exception occurred:

Traceback (most recent call last):
  File "/home/alessiatortone/miniconda3/envs/mldl/lib/python3.7/site-packages/wandb/sdk/lib/retry.py", line 131, in __call__
    result = self._call_fn(*args, **kwargs)
  File "/home/alessiatortone/miniconda3/envs/mldl/lib/python3.7/site-packages/wandb/sdk/internal/internal_api.py", line 340, in execute
    return self.client.execute(*args, **kwargs)  # type: ignore
  File "/home/alessiatortone/miniconda3/envs/mldl/lib/python3.7/site-packages/wandb/vendor/gql-0.2.0/wandb_gql/client.py", line 52, in execute
    result = self._get_result(document, *args, **kwargs)
  File "/home/alessiatortone/miniconda3/envs/mldl/lib/python3.7/site-packages/wandb/vendor/gql-0.2.0/wandb_gql/client.py", line 60, in _get_result
    return self.transport.execute(document, *args, **kwargs)
  File "/home/alessiatortone/miniconda3/envs/mldl/lib/python3.7/site-packages/wandb/sdk/lib/gql_request.py", line 58, in execute
    request = self.session.post(self.url, **post_args)
  File "/home/alessiatortone/miniconda3/envs/mldl/lib/python3.7/site-packages/requests/sessions.py", line 637, in post
    return self.request("POST", url, data=data, json=json, **kwargs)
  File "/home/alessiatortone/miniconda3/envs/mldl/lib/python3.7/site-packages/requests/sessions.py", line 589, in request
    resp = self.send(prep, **send_kwargs)
  File "/home/alessiatortone/miniconda3/envs/mldl/lib/python3.7/site-packages/requests/sessions.py", line 703, in send
    r = adapter.send(request, **kwargs)
  File "/home/alessiatortone/miniconda3/envs/mldl/lib/python3.7/site-packages/requests/adapters.py", line 519, in send
    raise ConnectionError(e, request=request)
requests.exceptions.ConnectionError: HTTPSConnectionPool(host='api.wandb.ai', port=443): Max retries exceeded with url: /graphql (Caused by NameResolutionError("<urllib3.connection.HTTPSConnection object at 0x7efd28452610>: Failed to resolve 'api.wandb.ai' ([Errno -3] Temporary failure in name resolution)"))
2024-05-28 11:55:02,697 INFO    MainThread:47574 [wandb_run.py:_on_init():2396] communicating current version
2024-05-28 11:55:02,797 INFO    MainThread:47574 [wandb_run.py:_on_init():2405] got version response 
2024-05-28 11:55:02,798 INFO    MainThread:47574 [wandb_init.py:init():795] starting run threads in backend
2024-05-28 11:55:04,713 INFO    MainThread:47574 [wandb_run.py:_console_start():2374] atexit reg
2024-05-28 11:55:04,713 INFO    MainThread:47574 [wandb_run.py:_redirect():2229] redirect: wrap_raw
2024-05-28 11:55:04,713 INFO    MainThread:47574 [wandb_run.py:_redirect():2294] Wrapping output streams.
2024-05-28 11:55:04,713 INFO    MainThread:47574 [wandb_run.py:_redirect():2319] Redirects installed.
2024-05-28 11:55:04,715 INFO    MainThread:47574 [wandb_init.py:init():838] run started, returning control to user process
2024-05-28 11:55:31,167 INFO    MainThread:47574 [wandb_run.py:_finish():2103] finishing run mldl_alessia/calGTT/5lpsqv81
2024-05-28 11:55:31,168 INFO    MainThread:47574 [wandb_run.py:_atexit_cleanup():2343] got exitcode: 0
2024-05-28 11:55:31,168 INFO    MainThread:47574 [wandb_run.py:_restore():2326] restore
2024-05-28 11:55:31,168 INFO    MainThread:47574 [wandb_run.py:_restore():2332] restore done
